# CRITICAL: Datetime Import Bug Breaking Ping Tasks

**Date:** 2025-10-23 16:20
**Status:** üö® CRITICAL - Production Bug
**Priority:** IMMEDIATE FIX REQUIRED

---

## üö® Critical Issue

**Problem:** Ping tasks failing to save results to database with timezone error

**Error Message:**
```
Failed to save ping record for 10.199.78.140: (builtins.AttributeError)
type object 'datetime.datetime' has no attribute 'timezone'
```

**Impact:**
- ‚ùå Ping results NOT being saved to database
- ‚ùå Device status NOT updating (shows stale data)
- ‚ùå Alerts NOT being created when devices go DOWN
- ‚ùå Real-time monitoring completely broken
- ‚ùå 6-minute delays (actually infinite - status never updates!)

---

## üîç Root Cause

**File:** `monitoring/tasks.py`
**Lines:** 191 (bug) and 236 (failure point)

### The Bug

**Line 191 (WRONG):**
```python
from datetime import datetime  # LOCAL import inside function
```

This **shadows the module-level import** on line 10:
```python
from datetime import datetime, timedelta, timezone  # MODULE import
```

**Line 236 tries to use `timezone.utc`:**
```python
down_since_aware = device.down_since.replace(tzinfo=timezone.utc)
```

### What Happens

1. Module-level import (line 10): `datetime`, `timedelta`, `timezone` all available
2. Function-level import (line 191): Shadows `datetime` with just the class
3. Line 236 tries: `timezone.utc`
4. Python looks for: `datetime.timezone` (because of line 191 shadow)
5. But `datetime` is the **class**, not the **module**!
6. **ERROR:** `AttributeError: type object 'datetime.datetime' has no attribute 'timezone'`

---

## ‚úÖ Solution

**Remove the shadowing local import** on line 191.

### Before (BROKEN):
```python
@shared_task(name="monitoring.tasks.ping_device")
def ping_device(device_id: str, device_ip: str):
    db = None
    try:
        from icmplib import ping
        from database import PingResult
        from datetime import datetime  # ‚ùå SHADOWS module import!
```

### After (FIXED):
```python
@shared_task(name="monitoring.tasks.ping_device")
def ping_device(device_id: str, device_ip: str):
    db = None
    try:
        from icmplib import ping
        from database import PingResult
        # NOTE: datetime, timezone already imported at module level (line 10)
```

---

## üéØ Why This Happened

This bug was introduced in the **idle transaction hotfix** (commit fb30bdd).

**Original hotfix goal:** Close DB session BEFORE SNMP polling to prevent idle transactions.

**What we did:**
- Added local import `from datetime import datetime` to avoid accessing closed session
- Didn't realize this would shadow the module-level `timezone` import!

**Lesson learned:** Be careful with local imports that shadow module-level imports!

---

## üìä Impact Analysis

### Before Fix (BROKEN)
```
1. Device goes DOWN at 15:41
2. Ping task runs at 15:41:30
3. Ping result created ‚úÖ
4. Try to save to database...
5. ‚ùå ERROR: datetime.timezone not found
6. Exception raised, db.commit() never reached
7. Ping result NOT saved ‚ùå
8. down_since NOT set ‚ùå
9. Alert NOT created ‚ùå
10. UI still shows UP (stale data) ‚ùå
11. Status NEVER updates (infinite delay!) ‚ùå
```

### After Fix (WORKING)
```
1. Device goes DOWN at 15:41
2. Ping task runs at 15:41:30
3. Ping result created ‚úÖ
4. Save to database ‚úÖ
5. down_since set ‚úÖ
6. Alert created ‚úÖ
7. UI shows DOWN within 30-60s ‚úÖ
```

---

## üöÄ Deployment

### Immediate Hotfix

```bash
cd /path/to/ward-ops-credobank
git pull origin main

# Rebuild worker container (includes celery-worker and celery-beat)
docker-compose -f docker-compose.production-local.yml build --no-cache celery-worker
docker-compose -f docker-compose.production-local.yml stop celery-worker celery-beat
docker-compose -f docker-compose.production-local.yml rm -f celery-worker celery-beat
docker-compose -f docker-compose.production-local.yml up -d celery-worker celery-beat

# Wait for workers to start
sleep 15

# Verify workers are healthy
docker ps | grep -E "(worker|beat)"

# Check logs for errors
docker logs wardops-worker-prod --tail 50
docker logs wardops-beat-prod --tail 50
```

**OR use the automated script:**

```bash
./deploy-datetime-hotfix.sh
```

---

## ‚úÖ Verification After Fix

### 1. Check Worker Logs (Should See NO Errors)

```bash
# Watch for ping tasks (should succeed)
docker logs wardops-worker-prod -f | grep -E "(ping|Failed)"

# Should see:
‚úÖ Ping tasks executing
‚úÖ NO "Failed to save ping record" errors
‚úÖ down_since timestamps being set
```

### 2. Check Database (Ping Results Should Be Fresh)

```bash
docker exec wardops-postgres-prod psql -U ward_admin -d ward_ops -c "
SELECT device_name, device_ip, is_reachable, timestamp, NOW() - timestamp AS age
FROM ping_results
ORDER BY timestamp DESC
LIMIT 10;
"

# Should see:
‚úÖ Age < 1 minute (fresh results)
‚úÖ Timestamps updating every 30 seconds
```

### 3. Test Real-Time Status Update

1. **Disconnect a test device** (unplug network cable)
2. **Wait 30-60 seconds**
3. **Check dashboard:**
   - Should show RED status ‚úÖ
   - Should show "Down Xm Ys" ‚úÖ
   - Alert should appear ‚úÖ
4. **Reconnect device**
5. **Wait 30-60 seconds**
6. **Check dashboard:**
   - Should show GREEN status ‚úÖ
   - "Down since" should clear ‚úÖ
   - Alert should be resolved ‚úÖ

---

## üîß Files Changed

**monitoring/tasks.py:**
- **Line 191:** Removed `from datetime import datetime` (shadowing import)
- **Added comment:** Explaining why we don't re-import datetime

---

## üìù Related Issues

- ‚úÖ Idle transaction fix (fb30bdd) - introduced this bug
- üö® Real-time status 6-minute delay - **caused by this bug!**
- üö® Batumi devices not visible - **caused by this bug!**
- üö® Kharagauli devices showing UP when DOWN - **caused by this bug!**

---

## üéâ Expected Results After Fix

1. **Ping tasks succeed** (no more datetime.timezone errors)
2. **Ping results saved** to database every 30 seconds
3. **Device status updates** within 30-60 seconds (real-time!)
4. **Alerts created immediately** when devices go DOWN
5. **Alerts resolved** when devices come back UP
6. **No more 6-minute delays!** ‚úÖ

---

## ‚ö†Ô∏è Why This Was So Critical

**This bug broke the entire real-time monitoring system!**

Without ping results being saved:
- ‚ùå Database has stale data (old timestamps)
- ‚ùå down_since never gets set
- ‚ùå Alerts never get created
- ‚ùå UI shows old status (cached from before bug)
- ‚ùå No visibility into actual device status

**User impact:**
- User sees devices as UP when they're actually DOWN
- No alerts in WARD OPS (but Zabbix working correctly)
- Complete loss of trust in monitoring system
- 6-minute delay is actually **infinite** (never updates!)

---

**Committed:** [COMMIT_SHA]
**Status:** ‚úÖ FIXED - Ready for immediate deployment
**Priority:** üö® DEPLOY IMMEDIATELY - Production is broken!

---

**Created:** 2025-10-23 16:25
**Status:** Awaiting deployment to CredoBank server
**Urgency:** CRITICAL - Every minute counts!
