# Deploy Database.py DateTime Fix - 500 Errors

**Status:** üö® CRITICAL - User registration and config endpoints returning 500 errors
**Fix:** Same datetime.timezone bug as monitoring tasks
**Commit:** cc10095

---

## üö® Problem

**500 Internal Server Error on:**
- `/api/v1/auth/register` - User registration
- `/api/v1/config/georgian-cities` - Georgian cities config
- `/api/v1/config/monitored-hostgroups` - Monitored groups config

**Error:**
```python
AttributeError: type object 'datetime.datetime' has no attribute 'timezone'
File "/app/database.py", line 93
    created_at = Column(DateTime, default=lambda: datetime.now(datetime.timezone.utc))
```

**Root Cause:**
- Import: `from datetime import datetime` (only CLASS, not timezone)
- Usage: `datetime.timezone.utc` (tries to access module attribute on class)
- Same pattern as monitoring/tasks.py bug (commit 86f9746)

---

## ‚úÖ Fix Applied

**database.py Changes:**
```python
# Line 9 - BEFORE:
from datetime import datetime

# Line 9 - AFTER:
from datetime import datetime, timezone

# All occurrences - BEFORE:
datetime.timezone.utc

# All occurrences - AFTER:
timezone.utc
```

**Models Fixed:**
- User.created_at
- PingResult.timestamp
- SNMPMetric.timestamp
- NetworkMetric.timestamp
- Alert.last_calculated
- MonitoringItem.updated_at

---

## üöÄ Deployment (IMMEDIATE)

### **Step 1: Pull Latest Code**

```bash
cd /home/wardops/ward-flux-credobank
git pull origin main
```

**Expected:**
```
Updating 2f78a3e..cc10095
database.py | 16 ++++++++--------
1 file changed, 8 insertions(+), 8 deletions(-)
```

---

### **Step 2: Restart API Container**

```bash
docker-compose -f docker-compose.production-local.yml restart api
```

**Wait for restart:**
```bash
sleep 10
```

**Verify API is healthy:**
```bash
docker ps | grep api
```

**Expected:**
```
wardops-api-prod   Up X seconds (healthy)
```

---

### **Step 3: Test User Registration**

**Try creating a test user:**
```bash
curl -X POST http://localhost:5001/api/v1/auth/register \
  -H "Content-Type: application/json" \
  -d '{
    "username": "testuser",
    "email": "test@example.com",
    "full_name": "Test User",
    "password": "testpass123",
    "role": "viewer",
    "regions": "[\"Tbilisi\"]"
  }'
```

**Expected (Success):**
```json
{
  "id": "...",
  "username": "testuser",
  "email": "test@example.com",
  ...
}
```

**NOT Expected (Before Fix):**
```json
{
  "detail": "Internal server error"
}
```

---

### **Step 4: Test Config Endpoints**

```bash
# Test Georgian cities
curl http://localhost:5001/api/v1/config/georgian-cities

# Test monitored hostgroups
curl http://localhost:5001/api/v1/config/monitored-hostgroups
```

**Expected:** JSON response (not 500 error)

---

### **Step 5: Check API Logs (Verify No Errors)**

```bash
docker logs wardops-api-prod --tail 50 | grep -iE "(error|exception|500)"
```

**Expected:** No datetime.timezone errors

---

## ‚úÖ Verification

### **Before Fix:**
```
POST /api/v1/auth/register ‚Üí 500 Internal Server Error ‚ùå
GET /api/v1/config/georgian-cities ‚Üí 500 Internal Server Error ‚ùå
GET /api/v1/config/monitored-hostgroups ‚Üí 500 Internal Server Error ‚ùå

Error: AttributeError: datetime.datetime has no attribute 'timezone'
```

### **After Fix:**
```
POST /api/v1/auth/register ‚Üí 201 Created ‚úÖ
GET /api/v1/config/georgian-cities ‚Üí 200 OK ‚úÖ
GET /api/v1/config/monitored-hostgroups ‚Üí 200 OK ‚úÖ

No datetime errors in logs ‚úÖ
```

---

## üìä Impact

**Before Fix:**
- ‚ùå User registration completely broken
- ‚ùå Config endpoints failing
- ‚ùå Any database INSERT with created_at/timestamp failed
- ‚ùå Authentication system non-functional

**After Fix:**
- ‚úÖ User registration works
- ‚úÖ Config endpoints work
- ‚úÖ Database inserts succeed
- ‚úÖ Authentication system functional

---

## üîç Root Cause Analysis

**This is the THIRD instance of the same datetime.timezone bug:**

1. **monitoring/tasks.py line 191** (ping tasks)
   - Status: ‚úÖ FIXED in commit 86f9746
   - Impact: Real-time monitoring broken

2. **monitoring/tasks.py line 75-130** (SNMP tasks)
   - Status: ‚ö†Ô∏è Still broken (DetachedInstanceError)
   - Impact: SNMP polling broken + memory leak

3. **database.py line 9+93** (user creation)
   - Status: ‚úÖ FIXED in this commit (cc10095)
   - Impact: 500 errors on registration

**Pattern:**
```python
# WRONG (causes bug):
from datetime import datetime
... datetime.timezone.utc  # AttributeError!

# CORRECT:
from datetime import datetime, timezone
... timezone.utc  # Works!
```

---

## üéØ Related Fixes

| Issue | Status | Commit |
|-------|--------|--------|
| Real-time monitoring broken | ‚úÖ FIXED | 86f9746 |
| Memory exhaustion (87% RAM) | ‚úÖ FIXED | d8a2663 |
| 500 errors on registration | ‚úÖ FIXED | cc10095 |
| SNMP DetachedInstanceError | ‚ö†Ô∏è TODO | Next |

---

## üìù Files Changed

**This Commit (cc10095):**
- database.py:
  * Line 9: Added timezone import
  * Lines 93, 110, 130, 150, 170, 190: Fixed datetime.timezone.utc ‚Üí timezone.utc

---

## ‚ö†Ô∏è Next Steps

1. **Deploy this fix IMMEDIATELY** (user registration broken!)
2. **Test user registration** (verify 500 errors gone)
3. **Deploy permanent memory fixes** (docker-compose changes from d8a2663)
4. **Fix SNMP DetachedInstanceError** (next commit)

---

**Deploy NOW - user registration is completely broken until this fix is deployed!**

---

**Created:** 2025-10-23 16:50
**Status:** Ready for immediate deployment
**Priority:** üö® CRITICAL - User authentication broken
**Commit:** cc10095
